<?xml version="1.0"?>

    <link name="world"></link>

    <link name="base_link">
        <inertial>
            <origin xyz="0.112849924193879 -0.232793382157193 0.183076177862911" rpy="0 0 0" />
            <mass value="45.6227535447207" />
            <inertia ixx="1.84588066123249" ixy="1.04398822934646E-09" ixz="-2.19695722124988E-08" iyy="1.12675188376899" iyz="-5.73876173682645E-05" izz="2.83493149680154" />
        </inertial>
        <visual>
            <origin xyz="0 0 0" rpy="0 0 0" />
            <geometry>
                <mesh filename="/home/emile/ros2_ws/src/rover_sim/meshes/base_link.STL" />
            </geometry>
            <material name="">
                <color rgba="0.792156862745098 0.819607843137255 0.933333333333333 1" />
            </material>
        </visual>
        <collision>
            <origin xyz="0 0 0" rpy="0 0 0" />
            <geometry>
                <mesh filename="/home/emile/ros2_ws/src/rover_sim/meshes/base_link.STL" />
            </geometry>
        </collision>
    </link>

    <link name="ROCKER_L">
        <inertial>
            <origin xyz="0.0576803895536336 0.0340847304368007 0.031349999159246" rpy="0 0 0" />
            <mass value="6.7188177795508" />
            <inertia ixx="0.0336800630880808" ixy="-0.0365712848373038" ixz="1.472561846937E-09" iyy="0.459728619591422" iyz="7.0337085870288E-10" izz="0.489006412488076" />
        </inertial>
        <visual>
            <origin xyz="0 0 0" rpy="0 0 0" />
            <geometry>
                <mesh filename="/home/emile/ros2_ws/src/rover_sim/meshes/ROCKER_L.STL" />
            </geometry>
            <material name="">
                <color rgba="0.792156862745098 0.819607843137255 0.933333333333333 1" />
            </material>
        </visual>
        <collision>
            <origin xyz="0 0 0" rpy="0 0 0" />
            <geometry>
                <mesh filename="/home/emile/ros2_ws/src/rover_sim/meshes/ROCKER_L.STL" />
            </geometry>
        </collision>
    </link>

    <link name="ROCKER_R">
        <inertial>
            <origin xyz="0.0576803900595149 0.0340847288843424 0.0313499999163654" rpy="0 0 0" />
            <mass value="6.71881777955079" />
            <inertia ixx="0.0336800620025095" ixy="-0.0365712785139467" ixz="6.60208857696379E-10" iyy="0.459728620676994" iyz="5.30271193571037E-11" izz="0.489006412488076" />
        </inertial>
        <visual>
            <origin xyz="0 0 0" rpy="0 0 0" />
            <geometry>
                <mesh filename="/home/emile/ros2_ws/src/rover_sim/meshes/ROCKER_R.STL" />
            </geometry>
            <material name="">
                <color rgba="0.792156862745098 0.819607843137255 0.933333333333333 1" />
            </material>
        </visual>
        <collision>
            <origin xyz="0 0 0" rpy="0 0 0" />
            <geometry>
                <mesh filename="/home/emile/ros2_ws/src/rover_sim/meshes/ROCKER_R.STL" />
            </geometry>
        </collision>
    </link>

    <link name="WHEEL_FL">
        <inertial>
            <origin xyz="9.42478317611517E-11 2.81360871927372E-09 -0.0649999999999999" rpy="0 0 0" />
            <mass value="7.55389670370359" />
            <inertia ixx="0.045567622882308" ixy="1.52458161818203E-18" ixz="-3.52208858329878E-11" iyy="0.045567622882308" iyz="-1.05145916727233E-09" izz="0.0698584367158508" />
        </inertial>
        <visual>
            <origin xyz="0 0 0" rpy="0 0 0" />
            <geometry>
                <mesh filename="/home/emile/ros2_ws/src/rover_sim/meshes/WHEEL_FL.STL" />
            </geometry>
            <material name="">
                <color rgba="0.792156862745098 0.819607843137255 0.933333333333333 1" />
            </material>
        </visual>
        <collision>
            <origin xyz="0 0 0" rpy="0 0 0" />
            <geometry>
                <mesh filename="/home/emile/ros2_ws/src/rover_sim/meshes/WHEEL_FL.STL" />
            </geometry>
        </collision>
    </link>

    <link name="WHEEL_RL">
        <inertial>
            <origin xyz="9.42478872723029E-11 2.8136087197074E-09 -0.0650000000000001" rpy="0 0 0" />
            <mass value="7.55389670370359" />
            <inertia ixx="0.045567622882308" ixy="1.52458158197648E-18" ixz="-3.52208867726297E-11" iyy="0.045567622882308" iyz="-1.05145916727233E-09" izz="0.0698584367158508" />
        </inertial>
        <visual>
            <origin xyz="0 0 0" rpy="0 0 0" />
            <geometry>
                <mesh filename="/home/emile/ros2_ws/src/rover_sim/meshes/WHEEL_RL.STL" />
            </geometry>
            <material name="">
                <color rgba="0.792156862745098 0.819607843137255 0.933333333333333 1" />
            </material>
        </visual>
        <collision>
            <origin xyz="0 0 0" rpy="0 0 0" />
            <geometry>
                <mesh filename="/home/emile/ros2_ws/src/rover_sim/meshes/WHEEL_RL.STL" />
            </geometry>
        </collision>
    </link>

    <link name="WHEEL_FR">
        <inertial>
            <origin xyz="9.42478317611517E-11 2.81360889231239E-09 -0.0649999999999999" rpy="0 0 0" />
            <mass value="7.55389670370359" />
            <inertia ixx="0.045567622882308" ixy="1.52458164381907E-18" ixz="-3.52208928881465E-11" iyy="0.045567622882308" iyz="-1.05145923201004E-09" izz="0.0698584367158508" />
        </inertial>
        <visual>
            <origin xyz="0 0 0" rpy="0 0 0" />
            <geometry>
                <mesh filename="/home/emile/ros2_ws/src/rover_sim/meshes/WHEEL_FR.STL" />
            </geometry>
            <material name="">
                <color rgba="0.792156862745098 0.819607843137255 0.933333333333333 1" />
            </material>
        </visual>
        <collision>
            <origin xyz="0 0 0" rpy="0 0 0" />
            <geometry>
                <mesh filename="/home/emile/ros2_ws/src/rover_sim/meshes/WHEEL_FR.STL" />
            </geometry>
        </collision>
    </link>

    <link name="WHEEL_RR">
        <inertial>
            <origin xyz="9.42479150278785E-11 2.8136088918787E-09 -0.0649999999999999" rpy="0 0 0" />
            <mass value="7.55389670370359" />
            <inertia ixx="0.045567622882308" ixy="1.52458164726758E-18" ixz="-3.52208937162165E-11" iyy="0.045567622882308" iyz="-1.05145923201005E-09" izz="0.0698584367158508" />
        </inertial>
        <visual>
            <origin xyz="0 0 0" rpy="0 0 0" />
            <geometry>
                <mesh filename="/home/emile/ros2_ws/src/rover_sim/meshes/WHEEL_RR.STL" />
            </geometry>
            <material name="">
                <color rgba="0.792156862745098 0.819607843137255 0.933333333333333 1" />
            </material>
        </visual>
        <collision>
            <origin xyz="0 0 0" rpy="0 0 0" />
            <geometry>
                <mesh filename="/home/emile/ros2_ws/src/rover_sim/meshes/WHEEL_RR.STL" />
            </geometry>
        </collision>
    </link>

    <joint name="ROCKER_L_JOINT" type="revolute">
        <origin xyz="0.3766 -0.20681 0.078821" rpy="1.5708 0 1.5708" />
        <parent link="base_link" />
        <child link="ROCKER_L" />
        <axis xyz="0 0 1" />
        <limit lower="-0.35" upper="0.35" effort="0" velocity="0" />
    </joint>

    <joint name="ROCKER_R_JOINT" type="revolute">
        <origin xyz="-0.213600073527999 -0.206807226568189 0.0788212705195118" rpy="1.57079630458203 0 1.5707963267949" />
        <parent link="base_link" />
        <child link="ROCKER_R" />
        <axis xyz="0 0 1" />
        <limit lower="-0.35" upper="0.35" effort="0" velocity="0" />
    </joint>

    <joint name="WHEEL_FL_JOINT" type="revolute">
        <origin xyz="-0.37995 -0.082166 0.1927" rpy="0 0 3.1416" />
        <parent link="ROCKER_L" />
        <child link="WHEEL_FL" />
        <axis xyz="0 0 -1" />
        <limit lower="-9999" upper="9999" effort="0" velocity="20" />
    </joint>

    <joint name="WHEEL_RL_JOINT" type="revolute">
        <origin xyz="0.375460091610939 -0.0821661046351226 0.192700001280739" rpy="0 0 3.14159265358979" />
        <parent link="ROCKER_L" />
        <child link="WHEEL_RL" />
        <axis xyz="0 0 -0.999999999999999" />
        <limit lower="0" upper="0" effort="0" velocity="20" />
    </joint>

    <joint name="WHEEL_FR_JOINT" type="revolute">
        <origin xyz="-0.379949909887969 -0.0821661155180505 0" rpy="0 0 3.14159263874792" />
        <parent link="ROCKER_R" />
        <child link="WHEEL_FR" />
        <axis xyz="0 0 -0.999999999999999" />
        <limit lower="999" upper="100" effort="0" velocity="20" />
    </joint>

    <joint name="WHEEL_RR_JOINT" type="revolute">
        <origin xyz="0.375460090112031 -0.082166114488072 0" rpy="0 0 3.14159263874792" />
        <parent link="ROCKER_R" />
        <child link="WHEEL_RR" />
        <axis xyz="0 0 -0.999999999999999" />
        <limit lower="100" upper="100" effort="0" velocity="20" />
    </joint>

    <!-- <plugin name="gz::sim::systems::JointStatePublisher" filename="gz-sim-joint-state-publisher-system">
    </plugin>

    <plugin name="gz::sim::systems::OdometryPublisher" filename="gz-sim-odometry-publisher-system">
        <odom_frame>odom</odom_frame>
        <robot_base_frame>base_link</robot_base_frame>
        <dimensions>3</dimensions>
    </plugin>

    <plugin filename="gz-sim-apply-joint-force-system" name="gz::sim::systems::ApplyJointForce">
        <joint_name>motor_0</joint_name>
    </plugin>
    <plugin filename="gz-sim-apply-joint-force-system" name="gz::sim::systems::ApplyJointForce">
        <joint_name>motor_1</joint_name>
    </plugin>
    <plugin filename="gz-sim-apply-joint-force-system" name="gz::sim::systems::ApplyJointForce">
        <joint_name>motor_2</joint_name>
    </plugin>
    <plugin filename="gz-sim-apply-joint-force-system" name="gz::sim::systems::ApplyJointForce">
        <joint_name>motor_3</joint_name>
    </plugin> -->

</robot>