<robot name="rover">
<link name="poignet_rot_urdf">
<visual>
<origin xyz="0.45288000323034588446 -0.22547264176416789705 1.1595260583077366956" rpy="-3.1240888278314318249 -0.5884662455932884173 0.83159716380141945891" />
<geometry>
<mesh filename="package://rover_sim/rover_urdf/poignet_rot_urdf.stl"/>
</geometry>
<material name="poignet_rot_urdf_material">
<color rgba="0.76862745098039220171 0.88627450980392152857 0.95294117647058818044 1.0"/>
</material>
</visual>
<collision>
<origin xyz="0.45288000323034588446 -0.22547264176416789705 1.1595260583077366956" rpy="-3.1240888278314318249 -0.5884662455932884173 0.83159716380141945891" />
<geometry>
<mesh filename="package://rover_sim/rover_urdf/poignet_rot_urdf.stl"/>
</geometry>
</collision>
<inertial>
<origin xyz="0.97225224751874628204 0.38163212603867135986 -0.037103436055681671135" rpy="0 0 0"/>
<mass value="0.48250317769047762484" />
<inertia ixx="0.0017121450377194295626" ixy="-0.00059416186709262681746"  ixz="-0.00019675524627273967802" iyy="0.0015868875304742044267" iyz="-0.00019905800963871257518" izz="0.001284550919130597775" />
</inertial>
</link>

<link name="poignet_ud_urdf">
<visual>
<origin xyz="0 -1.1102230246251565404e-16 -1.3666500000000001425" rpy="5.5511151231257827021e-17 -9.8488717231067899186e-18 6.1920117045727847836e-17" />
<geometry>
<mesh filename="package://rover_sim/rover_urdf/poignet_ud_urdf.stl"/>
</geometry>
<material name="poignet_ud_urdf_material">
<color rgba="0.91764705882352937127 0.91764705882352937127 0.91764705882352937127 1.0"/>
</material>
</visual>
<collision>
<origin xyz="0 -1.1102230246251565404e-16 -1.3666500000000001425" rpy="5.5511151231257827021e-17 -9.8488717231067899186e-18 6.1920117045727847836e-17" />
<geometry>
<mesh filename="package://rover_sim/rover_urdf/poignet_ud_urdf.stl"/>
</geometry>
</collision>
<inertial>
<origin xyz="-7.5623797925181782335e-17 -1.0920534506182438852e-16 -0.028463754227229909333" rpy="0 0 0"/>
<mass value="0.25422798910091382041" />
<inertia ixx="0.00015018464899557083694" ixy="6.8662273084827747693e-21"  ixz="-5.3128849058181258863e-21" iyy="0.0001141877223563912111" iyz="6.3386919244785128792e-21" izz="0.0001195825672440762222" />
</inertial>
</link>

<link name="j2_urdf">
<visual>
<origin xyz="0 1.335650000000000226 0.021999999999999964029" rpy="1.570796326794896558 1.570796326794896558 0" />
<geometry>
<mesh filename="package://rover_sim/rover_urdf/j2_urdf.stl"/>
</geometry>
<material name="j2_urdf_material">
<color rgba="0.2313725490196078538 0.38039215686274507888 0.7058823529411765163 1.0"/>
</material>
</visual>
<collision>
<origin xyz="0 1.335650000000000226 0.021999999999999964029" rpy="1.570796326794896558 1.570796326794896558 0" />
<geometry>
<mesh filename="package://rover_sim/rover_urdf/j2_urdf.stl"/>
</geometry>
</collision>
<inertial>
<origin xyz="-2.5281640684221690945e-17 0.26792712138606122885 0.02199999999999995709" rpy="0 0 0"/>
<mass value="1.903643385227656859" />
<inertia ixx="0.084156005789429416675" ixy="4.6715967643956255825e-18"  ixz="1.2687425686584875577e-17" iyy="0.0033583557704155351208" iyz="1.3881494277549246653e-18" izz="0.081582320035469349517" />
</inertial>
</link>

<link name="j1_urdf">
<visual>
<origin xyz="-5.5511151231257827021e-17 0.71065000000000011493 -0.02200000000000001954" rpy="1.570796326794896558 1.570796326794896558 0" />
<geometry>
<mesh filename="package://rover_sim/rover_urdf/j1_urdf.stl"/>
</geometry>
<material name="j1_urdf_material">
<color rgba="0.64705882352941179736 0.64705882352941179736 0.64705882352941179736 1.0"/>
</material>
</visual>
<collision>
<origin xyz="-5.5511151231257827021e-17 0.71065000000000011493 -0.02200000000000001954" rpy="1.570796326794896558 1.570796326794896558 0" />
<geometry>
<mesh filename="package://rover_sim/rover_urdf/j1_urdf.stl"/>
</geometry>
</collision>
<inertial>
<origin xyz="-0.0032239444370049147488 0.27551528650398626752 -0.02200000000000001607" rpy="0 0 0"/>
<mass value="3.5446627968758885885" />
<inertia ixx="0.17868771986117007455" ixy="-0.0018243125395202963029"  ixz="1.0772531916704006045e-17" iyy="0.01450135376998703228" iyz="-1.9452810805930548613e-17" izz="0.16547747611338786689" />
</inertial>
</link>

<link name="j0_urdf">
<visual>
<origin xyz="1.0408340855860842566e-16 -0.060650000000000037215 -0.055249999999999965805" rpy="-1.570796326794896558 -1.570796326794896558 0" />
<geometry>
<mesh filename="package://rover_sim/rover_urdf/j0_urdf.stl"/>
</geometry>
<material name="j0_urdf_material">
<color rgba="0.98039215686274505668 0.71372549019607844922 0.0039215686274509803377 1.0"/>
</material>
</visual>
<collision>
<origin xyz="1.0408340855860842566e-16 -0.060650000000000037215 -0.055249999999999965805" rpy="-1.570796326794896558 -1.570796326794896558 0" />
<geometry>
<mesh filename="package://rover_sim/rover_urdf/j0_urdf.stl"/>
</geometry>
</collision>
<inertial>
<origin xyz="0.021957787856313731173 0.0088785262004007492465 -0.055249999999999965805" rpy="0 0 0"/>
<mass value="3.9360055793372801247" />
<inertia ixx="0.01575767209281605033" ixy="-0.0018060990321288419337"  ixz="9.6855278146216311979e-19" iyy="0.0037724496376596583502" iyz="2.136354478126242902e-34" izz="0.017447895782726697417" />
</inertial>
</link>

<link name="jlin_urdf">
<visual>
<origin xyz="0 0 0.020850000000000007416" rpy="0 -0 1.4585192057487050876e-62" />
<geometry>
<mesh filename="package://rover_sim/rover_urdf/jlin_urdf.stl"/>
</geometry>
<material name="jlin_urdf_material">
<color rgba="0.97254901960784312376 0.52941176470588235947 0.0039215686274509803377 1.0"/>
</material>
</visual>
<collision>
<origin xyz="0 0 0.020850000000000007416" rpy="0 -0 1.4585192057487050876e-62" />
<geometry>
<mesh filename="package://rover_sim/rover_urdf/jlin_urdf.stl"/>
</geometry>
</collision>
<inertial>
<origin xyz="5.8914361214908327552e-18 0.016762797536052958386 -0.012676765453219690505" rpy="0 0 0"/>
<mass value="0.57976963990118524084" />
<inertia ixx="0.0004532818170395352432" ixy="-9.7300324602490568013e-36"  ixz="7.6463116774713202173e-38" iyy="0.000432021455082067993" iyz="-3.3950253613312331747e-06" izz="0.00071404810579741673053" />
</inertial>
</link>

<link name="base_urdf">
<visual>
<origin xyz="-0.016000000000000014211 -0.052850000000000008082 0" rpy="1.570796326794896558 1.570796326794896558 0" />
<geometry>
<mesh filename="package://rover_sim/rover_urdf/base_urdf.stl"/>
</geometry>
<material name="base_urdf_material">
<color rgba="0.49803921568627451677 0.49803921568627451677 0.49803921568627451677 1.0"/>
</material>
</visual>
<collision>
<origin xyz="-0.016000000000000014211 -0.052850000000000008082 0" rpy="1.570796326794896558 1.570796326794896558 0" />
<geometry>
<mesh filename="package://rover_sim/rover_urdf/base_urdf.stl"/>
</geometry>
</collision>
<visual>
<origin xyz="-0.071283110000000149409 0.27533012000000034458 -0.45644999999999985585" rpy="-1.570796326794896558 6.6560138878025349628e-31 -3.1415926535897922278" />
<geometry>
<mesh filename="package://rover_sim/rover_urdf/base.stl"/>
</geometry>
<material name="base_material">
<color rgba="0.64705882352941179736 0.64705882352941179736 0.64705882352941179736 1.0"/>
</material>
</visual>
<collision>
<origin xyz="-0.071283110000000149409 0.27533012000000034458 -0.45644999999999985585" rpy="-1.570796326794896558 6.6560138878025349628e-31 -3.1415926535897922278" />
<geometry>
<mesh filename="package://rover_sim/rover_urdf/base.stl"/>
</geometry>
</collision>
<inertial>
<origin xyz="0.30398924240666441721 0.16201320073831901314 -1.3010459126632932011e-19" rpy="0 0 0"/>
<mass value="703.12321350783213347" />
<inertia ixx="61.444137261695992436" ixy="-0.061802865570381372573"  ixz="5.9323197486898583997e-15" iyy="111.09797045647874825" iyz="4.0139229664524789115e-15" izz="63.968571228990157351" />
</inertial>
</link>

<joint name="base_lin" type="prismatic">
<origin xyz="0.22341873687837626727 0.0159999999999999587 -0.031999999999999861888" rpy="-1.5707963267948972241 -7.4246164771810203262e-16 1.5707963267948961139" />
<parent link="jlin_urdf" />
<child link="base_urdf" />
<axis xyz="0 0 1"/>
<limit effort="1" velocity="20" lower="-0.23250000000000001221" upper="0.23250000000000001221"/>
<joint_properties friction="0.0"/>
</joint>

<joint name="J0" type="revolute">
<origin xyz="1.3877787807814456755e-16 -0.081500000000000044631 -0.055250000000000076827" rpy="-1.570796326794896558 0.70767284743509584199 -1.667175257035190381e-17" />
<parent link="j0_urdf" />
<child link="jlin_urdf" />
<axis xyz="0 0 1"/>
<limit effort="1" velocity="20" lower="-3.141592653589793116" upper="3.141592653589793116"/>
<joint_properties friction="0.0"/>
</joint>

<joint name="J1" type="revolute">
<origin xyz="5.5511151231257827021e-17 0.65000000000000057732 -0.077250000000000262901" rpy="3.1415926535897926719 -1.1102230246251438447e-16 -1.0209549457332056654" />
<parent link="j1_urdf" />
<child link="j0_urdf" />
<axis xyz="0 0 1"/>
<limit effort="1" velocity="20" lower="-3.141592653589793116" upper="3.141592653589793116"/>
<joint_properties friction="0.0"/>
</joint>

<joint name="J2" type="revolute">
<origin xyz="0 0.62500000000000044409 0.043999999999999539479" rpy="7.6620089321465238822e-15 -5.3667135120133940592e-15 -1.7054038722282933715" />
<parent link="j2_urdf" />
<child link="j1_urdf" />
<axis xyz="0 0 1"/>
<limit effort="1" velocity="20" lower="-3.141592653589793116" upper="3.141592653589793116"/>
<joint_properties friction="0.0"/>
</joint>

<joint name="poignet_ud" type="revolute">
<origin xyz="0.02199999999999951994 -4.4408920985006261617e-16 -0.030999999999999916511" rpy="-1.570796326794896558 0.17346192190115755638 1.5707963267948901187" />
<parent link="poignet_ud_urdf" />
<child link="j2_urdf" />
<axis xyz="0 0 1"/>
<limit effort="1" velocity="20" lower="-3.141592653589793116" upper="3.141592653589793116"/>
<joint_properties friction="0.0"/>
</joint>

<joint name="poignet_gd" type="revolute">
<origin xyz="0.9461958637762555302 0.35117428972622033445 0.022930263560738683992" rpy="-2.5528968960603362071 -1.883985361725510729e-16 -0.70767284743509584199" />
<parent link="poignet_rot_urdf" />
<child link="poignet_ud_urdf" />
<axis xyz="0 0 1"/>
<limit effort="1" velocity="20" lower="-3.141592653589793116" upper="3.141592653589793116"/>
<joint_properties friction="0.0"/>
</joint>


</robot>
