<robot name="rover">
<link name="poignet_rot_urdf">
<visual>
<origin xyz="0.081754356718666765236 0.50263140421496166343 1.0505725294460097619" rpy="-2.8581940253805386831 -0.37952036589919524445 0.90457665608242654454" />
<geometry>
<mesh filename="package://rover_sim/rover_urdf/poignet_rot_urdf.stl"/>
</geometry>
<material name="poignet_rot_urdf_material">
<color rgba="0.76862745098039220171 0.88627450980392152857 0.95294117647058818044 1.0"/>
</material>
</visual>
<collision>
<origin xyz="0.081754356718666765236 0.50263140421496166343 1.0505725294460097619" rpy="-2.8581940253805386831 -0.37952036589919524445 0.90457665608242654454" />
<geometry>
<mesh filename="package://rover_sim/rover_urdf/poignet_rot_urdf.stl"/>
</geometry>
</collision>
<inertial>
<origin xyz="0.081754356686861859305 1.1536272902799651341 -0.23256823848750141082" rpy="0 0 0"/>
<mass value="0.48250317769047756933" />
<inertia ixx="0.0017918646082511510524" ixy="-0.00057916823760827216422"  ixz="-0.00029383848557779237249" iyy="0.0013515182367600472348" iyz="-6.0587946204784955649e-05" izz="0.0014402006423130332604" />
</inertial>
</link>

<link name="poignet_ud_urdf">
<visual>
<origin xyz="1.3877787807814456755e-17 0 -1.3666500000000001425" rpy="-5.5511151231257827021e-17 -0 1.6155871338926321775e-27" />
<geometry>
<mesh filename="package://rover_sim/rover_urdf/poignet_ud_urdf.stl"/>
</geometry>
<material name="poignet_ud_urdf_material">
<color rgba="0.91764705882352937127 0.91764705882352937127 0.91764705882352937127 1.0"/>
</material>
</visual>
<collision>
<origin xyz="1.3877787807814456755e-17 0 -1.3666500000000001425" rpy="-5.5511151231257827021e-17 -0 1.6155871338926321775e-27" />
<geometry>
<mesh filename="package://rover_sim/rover_urdf/poignet_ud_urdf.stl"/>
</geometry>
</collision>
<inertial>
<origin xyz="1.4255737149243102446e-17 1.6339849340751862521e-18 -0.028463754227229909333" rpy="0 0 0"/>
<mass value="0.25422798910091382041" />
<inertia ixx="0.00015018464899557086405" ixy="5.8156171537935595981e-32"  ixz="3.8639211415476012488e-31" iyy="0.0001141877223563912111" iyz="-6.3386919244785128792e-21" izz="0.0001195825672440762222" />
</inertial>
</link>

<link name="j2_urdf">
<visual>
<origin xyz="-1.1102230246251565404e-16 1.335650000000000226 0.021999999999999977907" rpy="1.57079632679489678 1.570796326794896558 0" />
<geometry>
<mesh filename="package://rover_sim/rover_urdf/j2_urdf.stl"/>
</geometry>
<material name="j2_urdf_material">
<color rgba="0.2313725490196078538 0.38039215686274507888 0.7058823529411765163 1.0"/>
</material>
</visual>
<collision>
<origin xyz="-1.1102230246251565404e-16 1.335650000000000226 0.021999999999999977907" rpy="1.57079632679489678 1.570796326794896558 0" />
<geometry>
<mesh filename="package://rover_sim/rover_urdf/j2_urdf.stl"/>
</geometry>
</collision>
<inertial>
<origin xyz="-7.7148840691660847348e-17 0.26792712138606122885 0.021999999999999977907" rpy="0 0 0"/>
<mass value="1.9036433852276564149" />
<inertia ixx="0.084156005789429388919" ixy="-4.858022959455528708e-18"  ixz="2.7192272038639201853e-28" iyy="0.0033583557704155346871" iyz="-1.5094743254584045609e-44" izz="0.081582320035469349517" />
</inertial>
</link>

<link name="j1_urdf">
<visual>
<origin xyz="0 0.71065000000000000391 -0.022000000000000012601" rpy="1.570796326794896558 1.570796326794896558 0" />
<geometry>
<mesh filename="package://rover_sim/rover_urdf/j1_urdf.stl"/>
</geometry>
<material name="j1_urdf_material">
<color rgba="0.64705882352941179736 0.64705882352941179736 0.64705882352941179736 1.0"/>
</material>
</visual>
<collision>
<origin xyz="0 0.71065000000000000391 -0.022000000000000012601" rpy="1.570796326794896558 1.570796326794896558 0" />
<geometry>
<mesh filename="package://rover_sim/rover_urdf/j1_urdf.stl"/>
</geometry>
</collision>
<inertial>
<origin xyz="-0.0032239444370048605387 0.27551528650398621201 -0.022000000000000005662" rpy="0 0 0"/>
<mass value="3.5446627968758881444" />
<inertia ixx="0.1786877198611700468" ixy="-0.0018243125395202965198"  ixz="0" iyy="0.014501353769987028811" iyz="5.3468656271562979258e-28" izz="0.1654774761133879224" />
</inertial>
</link>

<link name="j0_urdf">
<visual>
<origin xyz="0 -0.060650000000000009459 -0.055250000000000021316" rpy="-1.570796326794896558 -1.570796326794896558 0" />
<geometry>
<mesh filename="package://rover_sim/rover_urdf/j0_urdf.stl"/>
</geometry>
<material name="j0_urdf_material">
<color rgba="0.98039215686274505668 0.71372549019607844922 0.0039215686274509803377 1.0"/>
</material>
</visual>
<collision>
<origin xyz="0 -0.060650000000000009459 -0.055250000000000021316" rpy="-1.570796326794896558 -1.570796326794896558 0" />
<geometry>
<mesh filename="package://rover_sim/rover_urdf/j0_urdf.stl"/>
</geometry>
</collision>
<inertial>
<origin xyz="0.02195778785631362709 0.008878526200400777002 -0.055250000000000021316" rpy="0 0 0"/>
<mass value="3.9360055793372801247" />
<inertia ixx="0.01575767209281604686" ixy="-0.0018060990321288410664"  ixz="-7.5294120389382387198e-36" iyy="0.0037724496376596583502" iyz="1.5726893726159169154e-35" izz="0.017447895782726693947" />
</inertial>
</link>

<link name="jlin_urdf">
<visual>
<origin xyz="0 0 0.020850000000000007416" rpy="0 1.5101180481950411466e-43 0" />
<geometry>
<mesh filename="package://rover_sim/rover_urdf/jlin_urdf.stl"/>
</geometry>
<material name="jlin_urdf_material">
<color rgba="0.97254901960784312376 0.52941176470588235947 0.0039215686274509803377 1.0"/>
</material>
</visual>
<collision>
<origin xyz="0 0 0.020850000000000007416" rpy="0 1.5101180481950411466e-43 0" />
<geometry>
<mesh filename="package://rover_sim/rover_urdf/jlin_urdf.stl"/>
</geometry>
</collision>
<inertial>
<origin xyz="5.6989693985371946758e-18 0.016762797536052961855 -0.012676765453219676627" rpy="0 0 0"/>
<mass value="0.57976963990118512982" />
<inertia ixx="0.00045328181703953518899" ixy="-1.569259435943403619e-38"  ixz="3.3004958975549432211e-36" iyy="0.00043202145508206804721" iyz="-3.3950253613312293631e-06" izz="0.00071404810579741694737" />
</inertial>
</link>

<link name="base_urdf">
<visual>
<origin xyz="-0.015999999999999903189 -0.052850000000000008082 3.4694469519536141888e-18" rpy="1.570796326794896558 1.570796326794896558 0" />
<geometry>
<mesh filename="package://rover_sim/rover_urdf/base_urdf.stl"/>
</geometry>
<material name="base_urdf_material">
<color rgba="0.49803921568627451677 0.49803921568627451677 0.49803921568627451677 1.0"/>
</material>
</visual>
<collision>
<origin xyz="-0.015999999999999903189 -0.052850000000000008082 3.4694469519536141888e-18" rpy="1.570796326794896558 1.570796326794896558 0" />
<geometry>
<mesh filename="package://rover_sim/rover_urdf/base_urdf.stl"/>
</geometry>
</collision>
<visual>
<origin xyz="-0.071283109999999982875 0.27533012000000056663 -0.45645000000000002238" rpy="-1.570796326794896558 1.1102230243784167497e-16 -3.1415926535897922278" />
<geometry>
<mesh filename="package://rover_sim/rover_urdf/base.stl"/>
</geometry>
<material name="base_material">
<color rgba="0.64705882352941179736 0.64705882352941179736 0.64705882352941179736 1.0"/>
</material>
</visual>
<collision>
<origin xyz="-0.071283109999999982875 0.27533012000000056663 -0.45645000000000002238" rpy="-1.570796326794896558 1.1102230243784167497e-16 -3.1415926535897922278" />
<geometry>
<mesh filename="package://rover_sim/rover_urdf/base.stl"/>
</geometry>
</collision>
<inertial>
<origin xyz="0.30398924240666463925 0.16201320073831923518 9.6891355419079148913e-17" rpy="0 0 0"/>
<mass value="703.1232135078319061" />
<inertia ixx="61.444137261696013752" ixy="-0.061802865570381990135"  ixz="1.3842256883336023346e-15" iyy="111.09797045647874825" iyz="5.3170248831144793314e-15" izz="63.968571228990185773" />
</inertial>
</link>

<joint name="base_lin" type="prismatic">
<origin xyz="-0.06385308179254031713 0.016000000000000014211 -0.032000000000000021483" rpy="-1.570796326794896558 2.5673907442389554717e-16 -1.5707963267948958919" />
<parent link="jlin_urdf" />
<child link="base_urdf" />
<axis xyz="0 0 1"/>
<limit effort="1" velocity="20" lower="-0.23250000000000001221" upper="0.23250000000000001221"/>
<joint_properties friction="0.0"/>
</joint>

<joint name="J0" type="revolute">
<origin xyz="0 -0.081500000000000044631 -0.055250000000000021316" rpy="-1.570796326794896558 -1.5707963267701074983 0" />
<parent link="j0_urdf" />
<child link="jlin_urdf" />
<axis xyz="0 0 1"/>
<limit effort="1" velocity="20" lower="-3.141592653589793116" upper="3.141592653589793116"/>
<joint_properties friction="0.0"/>
</joint>

<joint name="J1" type="revolute">
<origin xyz="-1.1102230246251565404e-16 0.65000000000000013323 -0.077250000000000040856" rpy="-3.1415926535897926719 4.6444468414471429881e-16 0.67872880729574947001" />
<parent link="j1_urdf" />
<child link="j0_urdf" />
<axis xyz="0 0 1"/>
<limit effort="1" velocity="20" lower="-3.141592653589793116" upper="3.141592653589793116"/>
<joint_properties friction="0.0"/>
</joint>

<joint name="J2" type="revolute">
<origin xyz="-1.1102230246251565404e-16 0.62500000000000011102 0.043999999999999983569" rpy="-3.9266894517977682624e-15 -8.8941013865064131739e-15 -0.20922196205218601683" />
<parent link="j2_urdf" />
<child link="j1_urdf" />
<axis xyz="0 0 1"/>
<limit effort="1" velocity="20" lower="-3.141592653589793116" upper="3.141592653589793116"/>
<joint_properties friction="0.0"/>
</joint>

<joint name="poignet_ud" type="revolute">
<origin xyz="0.02200000000000001954 2.2204460492503130808e-16 -0.031000000000000249578" rpy="2.0732686826105091365e-17 -1.570796326794891451 0" />
<parent link="poignet_ud_urdf" />
<child link="j2_urdf" />
<axis xyz="0 0 1"/>
<limit effort="1" velocity="20" lower="-3.141592653589793116" upper="3.141592653589793116"/>
<joint_properties friction="0.0"/>
</joint>

<joint name="poignet_gd" type="revolute">
<origin xyz="0.081754356688457471836 1.120967480656651194 -0.16819435518397995999" rpy="-2.6720858083462291077 2.478881469459590623e-11 -1.031381997923065086e-16" />
<parent link="poignet_rot_urdf" />
<child link="poignet_ud_urdf" />
<axis xyz="0 0 1"/>
<limit effort="1" velocity="20" lower="-3.141592653589793116" upper="3.141592653589793116"/>
<joint_properties friction="0.0"/>
</joint>


</robot>
